# [Domain](https://nodejs.org/docs/latest/api/domain.html#domain)

Node.js 的 `domain` 模块是一个用于简化多个不同 I/O 操作中错误处理的废弃（deprecated）模块。在 Node.js 中，I/O 操作通常是异步的，这意味着它们会在将来的某一时刻完成，而非立即执行。这种异步性质使得追踪和处理错误变得复杂，特别是当发生异常时，它可能会被抛出到原始操作的上下文之外。

`domain` 模块的主要目的是为了捕获这些异步操作中的错误，并将它们路由到一个集中的地方进行处理。然而，随着 Node.js 的发展，`domain` 模块由于许多设计上的问题被认为是有缺陷的，而且被标记为废弃（不推荐使用），因为它无法完美地解决异步错误处理的问题，并且可能隐藏潜在的 bug。

虽然你可能在查看 Node.js v21.7.1 的文档时遇到了 `domain` 模块，但是我们通常建议使用更现代和可靠的错误处理策略，比如使用 `async/await` 结合 try-catch 块来捕获异步错误，或者使用事件发射器 (EventEmitter) 和 Promises 来处理错误。

这里是一个替代 `domain` 的例子：

假设你有一个读取文件的异步操作，并希望捕获其中的错误：

不使用 `domain`，而使用 `async/await` 与 try-catch 可能像这样：

```javascript
const fs = require("fs").promises;

async function readFile(filePath) {
  try {
    const data = await fs.readFile(filePath, "utf8");
    console.log(data);
  } catch (error) {
    console.error("An error occurred:", error.message);
  }
}

readFile("path/to/myfile.txt");
```

在这个例子中，`try` 块尝试执行 `fs.readFile` 来异步读取文件内容。如果成功，它会打印文件内容。如果出现错误（例如文件不存在），则会自动跳转到 `catch` 块，输出错误消息。

总结一下，尽管 `domain` 模块存在于 Node.js 文档中并可以使用，推荐的做法是使用其他更可靠的方法来处理异步错误。如果你正在学习 Node.js，关注现代的错误处理方式将会对你更加有益。

## [Warning: Don't ignore errors!](https://nodejs.org/docs/latest/api/domain.html#warning-dont-ignore-errors)

在 Node.js 中，"Warning: Don't ignore errors!" 是一句警告，提醒开发者不要忽视错误处理。错误处理在编程中非常重要，特别是在 Node.js 这样的异步环境中。如果错误没有被正确地捕获和处理，程序可能会行为异常、崩溃或产生安全问题。

在 Node.js 中，有一个模块叫做 `domain`（域），它曾经被用来作为异步操作错误处理的一种方法。但是，`domain` 模块现在已经不推荐使用了，因为它有许多问题和局限性。即使如此，某些 Node.js 版本的文档中仍然提及了它，通常会伴随着一个警告，提醒开发者“不要忽视错误”，并推荐更好的错误处理方式。

下面是几个关于如何正确处理错误的例子：

### 1. 异步回调中的错误处理

在 Node.js 中，很多异步 API 都使用回调函数。传统的错误处理方法是检查回调函数的第一个参数是否存在错误。

```javascript
const fs = require("fs");

fs.readFile("/path/to/file.txt", "utf-8", (err, data) => {
  if (err) {
    // 错误处理
    console.error("发生错误:", err);
    return;
  }
  // 正常处理数据
  console.log(data);
});
```

在上面的代码中，我们使用了 `fs.readFile` 方法来读取文件内容。如果发生错误（例如文件不存在），则 `err` 参数会包含错误信息，我们需要检查并处理它。如果一切正常，则可以处理读取到的数据。

### 2. Promises 和 Async/Await 的错误处理

使用 Promises 时，应当使用 `.catch()` 方法来捕获任何可能出现的错误。

```javascript
const fs = require("fs").promises;

fs.readFile("/path/to/file.txt", "utf-8")
  .then((data) => {
    // 正常处理数据
    console.log(data);
  })
  .catch((err) => {
    // 错误处理
    console.error("发生错误:", err);
  });
```

在 ES7 中引入了 `async/await` 语法，它使得异步代码看起来像同步代码，并且可以使用标准的 `try...catch` 语法来捕获错误。

```javascript
const fs = require("fs").promises;

async function readFile() {
  try {
    const data = await fs.readFile("/path/to/file.txt", "utf-8");
    // 正常处理数据
    console.log(data);
  } catch (err) {
    // 错误处理
    console.error("发生错误:", err);
  }
}

readFile();
```

### 3. 使用事件发射器处理错误

在 Node.js 中，有一些对象是基于事件的，如 streams。对于这些对象，你应该监听 `error` 事件来处理可能发生的错误。

```javascript
const fs = require("fs");

const readStream = fs.createReadStream("/path/to/file.txt", "utf-8");

readStream.on("data", (chunk) => {
  // 处理数据片段
  console.log(chunk);
});

readStream.on("error", (err) => {
  // 错误处理
  console.error("流错误:", err);
});
```

以上就是错误处理在 Node.js 中的一些常见模式。无论使用哪种模式，关键是要确保你的程序能够优雅地处理所有预期内外的错误情况，从而提高程序的稳定性和可靠性。

## [Additions to Error objects](https://nodejs.org/docs/latest/api/domain.html#additions-to-error-objects)

Node.js v21.7.1 版本中关于 Error 对象的新增特性，主要指的是在错误（`Error`）对象上添加了额外的属性或方法使得错误处理更加丰富和详细。这些特性能够帮助开发者更好地理解和追踪程序中出现的错误。

在 Node.js 官方文档中的“Additions to Error objects”部分提到的新增特性可能包括以下几点：

1. `code`：一个标识错误类型的字符串。通过这个`code`属性，你可以知道错误的具体种类，比如是"ENOENT"(文件不存在)、"ECONNREFUSED"(连接被拒绝)等等。

2. `stack`：一个表示错误调用栈的字符串。它会告诉你错误在哪里被抛出，以及它之前经过了哪些函数调用。

3. `message`：错误信息字符串，给出了错误发生时的具体描述。

4. 其他自定义属性：开发者可以根据需要向`Error`对象添加其他有用的属性。

### 实际运用例子：

假设你正在使用 Node.js 编写一个读取文件内容的脚本，代码可能是这样的：

```javascript
const fs = require("fs");

fs.readFile("/path/to/file.txt", "utf8", (err, data) => {
  if (err) {
    // 处理错误
    console.error("错误码:", err.code);
    console.error("错误信息:", err.message);
    console.error("错误栈:", err.stack);
    return;
  }

  // 使用文件内容data进行后续操作
  console.log(data);
});
```

在上面的例子中，如果读取文件出错（例如文件不存在），Node.js 就会回调传递一个 Error 对象`err`。这个 Error 对象会包含一些属性，比如`code`、`message`和`stack`等，你可以使用这些属性来获取错误详情，并据此处理错误。

- `err.code`: 如果文件不存在，通常是"ENOENT"。
- `err.message`: 会告诉你错误的详细信息，比如"ENOENT: no such file or directory, open '/path/to/file.txt'"。
- `err.stack`: 这将给出错误发生时的 JavaScript 调用栈，帮助你定位问题所在。

当然，这只是一个简单的例子，Node.js 中的 Error 对象和错误处理是一个宽泛而深入的话题，随着你对 Node.js 的学习深入，你会遇到更复杂的场景和更多的错误处理方式。

## [Implicit binding](https://nodejs.org/docs/latest/api/domain.html#implicit-binding)

Node.js 中的 `domain` 模块是一个已被弃用的功能，它曾经用于简化多个异步操作中异常处理的复杂性。当你在 Node.js v21.7.1 或其他版本中查阅关于 `domain` 模块的文档时，你会遇到一个名为“隐式绑定”（Implicit Binding）的概念。尽管这部分 API 被弃用，但我会尽量以通俗易懂的方式解释这一概念。

隐式绑定是指 `domain` 模块能够自动将异步操作相关的回调函数与一个特定的域相关联。在 Node.js 中，“域”可以被看作是一个管理一组异步操作错误的上下文环境。

让我们通过一个简化的例子来理解什么是隐式绑定：

假设你有以下代码，用于读取一个文件并处理其中的数据：

```javascript
const fs = require("fs");
const domain = require("domain");

// 创建一个新的域
const d = domain.create();

// 当发生错误时的处理逻辑
d.on("error", (err) => {
  console.error(`捕获到错误: ${err.message}`);
});

// 隐式绑定发生在这里
d.run(() => {
  // fs.readFile 是一个异步操作
  fs.readFile("不存在的文件.txt", "utf8", (err, data) => {
    if (err) throw err; // 故意抛出错误来演示
    console.log(data);
  });
});
```

在上面的代码中，我们首先引入了 `fs` 和 `domain` 模块，然后创建了一个新的域 `d`。在域 `d` 上，我们设置了一个错误事件的监听器，这意味着如果在域内的任何异步操作中出现了错误，都会执行这个错误处理函数。

接着通过调用 `d.run` 方法，我们传入了一个包含异步操作的函数。在这个函数里，我们使用 `fs.readFile` 来异步读取一个文件。由于该文件不存在，读取操作将会失败并产生一个错误。

重点来了：正常情况下（没有使用 `domain` 模块），异步操作的错误可能很难跟踪和管理，因为它们可能不会导致进程崩溃，也可能在错误发生时没有足够的上下文信息。但是，在上述例子中，由于 `fs.readFile` 被隐式绑定到域 `d`，当异步操作抛出错误时，它会被 `d` 域捕获并触发我们定义的错误处理逻辑。

简单来说，隐式绑定就是 `domain` 模块提供的一种机制，它允许你将一组异步操作放在一个域的上下文中，使得任何在这组操作中产生的错误都能被统一处理。

最后需要提醒的是，由于 `domain` 模块已被弃用，当前 Node.js 社区推荐使用其他错误处理策略，如使用 `async/await` 结合 `try/catch`，或者使用 Promise-based 的库和工具来更优雅地处理异步操作中的错误。

## [Explicit binding](https://nodejs.org/docs/latest/api/domain.html#explicit-binding)

Node.js 中的 "Explicit Binding"（显式绑定）通常与 `domain` 模块有关。不过，值得注意的是，截至我所知最新信息，`domain` 模块已被废弃，因为它有一些难以修复的设计问题。但是，我仍然可以解释一下显式绑定的概念，并用类似的场景给你举一些例子。

在 Node.js 中，显式绑定涉及到将一个函数或者资源如事件监听器、定时器等明确地绑定到一个特定的上下文或者作用域中。这通常用于错误处理和资源管理，特别是在异步编程中。

例如，在传统的 JavaScript 中，你可能使用 `try-catch` 块来捕获同步代码中的错误：

```javascript
try {
  // 同步代码，可能会抛出错误
  var result = syncOperation();
  console.log(result);
} catch (error) {
  console.error("An error occurred:", error);
}
```

但是，这种方法并不能捕获异步操作中抛出的错误。在早期的 Node.js 版本中，`domain` 模块被提出来帮助处理异步代码中的异常，通过显式地将回调函数和事件绑定到一个特定的域中。

```javascript
const domain = require("domain");

var d = domain.create();

d.on("error", function (err) {
  console.error("Domain caught an error:", err);
});

d.run(function () {
  // 异步操作，例如一个网络请求
  process.nextTick(function () {
    throw new Error("Asynchronous error from nextTick");
  });
});
```

在此示例中，我们创建了一个新的域 `d` 并为其添加了一个错误事件监听器。当在该域内部运行的任何异步操作产生未捕获的异常时，它们都会被这个域捕获。

现代 Node.js 中推荐的做法是使用 Promises 和 async/await 来处理异步错误。Promises 允许你更容易地组织和管理异步代码，并且通过 `.catch()` 方法来处理错误。

下面是一个使用 Promise 的例子：

```javascript
function asyncOperation() {
  return new Promise((resolve, reject) => {
    // 异步操作，例如读取文件或数据库操作
    setTimeout(() => {
      if(/* operation is successful */) {
        resolve('Success!');
      } else {
        reject(new Error('Operation failed'));
      }
    }, 1000);
  });
}

asyncOperation()
  .then(result => {
    console.log(result); // 处理成功的结果
  })
  .catch(error => {
    console.error('An error occurred:', error); // 处理发生的错误
  });
```

如果我们使用 `async/await`，则可以按以下方式重写：

```javascript
async function performAsyncOperation() {
  try {
    const result = await asyncOperation(); // 等待 Promise 解决
    console.log(result); // 处理成功的结果
  } catch (error) {
    console.error("An error occurred:", error); // 错误在这里被捕获
  }
}

performAsyncOperation();
```

在这些现代化的错误处理方法中，显式绑定变得不那么必要，因为 Promise 已经为我们提供了一个清晰的上下文来处理异步操作的结果和错误。有鉴于此，Node.js 社区和核心团队正在逐渐放弃 `domain` 模块，并寻求其他的方法来改进错误处理。

## [domain.create()](https://nodejs.org/docs/latest/api/domain.html#domaincreate)

好的，让我们来聊一聊 Node.js 中的 `domain.create()` 函数。

首先，要了解 `domain` 模块是 Node.js 提供的一个比较老的 API，用于处理多个异步操作中的异常。不过需要提醒的是，这个模块已经被标记为 Deprecated（不推荐使用），因为它可能会引起内存泄漏等问题，并且 Node.js 社区和核心团队正在寻找替代方案。

即使如此，理解这个函数在旧代码或遗留系统中的作用还是有帮助的。

简单来说，`domain.create()` 是 `domain` 模块中的一个方法，当你调用它时，它会返回一个新的 Domain 对象。Domain 对象基本上是一个事件触发器，它可以捕获在其上下文中发生的错误（error 事件）。当你在 Node.js 写异步代码时，异常处理变得复杂，因为错误可能在任何回调中发生。Domain 的设计初衷就是为了简化这种情况的错误处理。

下面是一个简单的例子来展示 `domain.create()` 的用法：

```javascript
const domain = require("domain");
const fs = require("fs");

// 创建一个新的 domain 实例
const d = domain.create();

d.on("error", function (err) {
  console.log("捕获到错误:", err);
});

// 在 domain 的上下文中运行一些异步代码
d.run(function () {
  fs.readFile("不存在的文件.txt", function (err, data) {
    if (err) throw err; // 这里的错误会被 domain 捕获
    console.log(data);
  });
});
```

在这个例子中，我们使用 `domain.create()` 创建了一个新的 Domain 实例 `d`。通过监听 `d` 上的 `'error'` 事件，我们可以捕获在这个 domain 上下文中运行的所有异步操作中抛出的错误。接着，我们使用 `d.run()` 方法运行了一个读取文件内容的异步操作。如果文件不存在，则 `fs.readFile` 函数将会产生一个错误。正常情况下这个错误会导致程序崩溃，但是由于它发生在 domain 的上下文中，错误被捕获并传递给了 `d.on('error', ...)` 中定义的错误处理函数。这样我们就可以安全地处理错误而不会导致整个程序崩溃。

尽管 `domain` 模块提供了一种错误处理的方式，但是在新的 Node.js 项目中建议使用 Promise、async/await 或者其他现代的错误处理机制，以及使用 try/catch 语句来处理异常，因为这些方法更加稳定和可靠。

## [Class: Domain](https://nodejs.org/docs/latest/api/domain.html#class-domain)

`Domain` 是 Node.js 中一个处理异步操作中多个对象作为一个组进行错误处理的模块。但是，首先需要知道的是，截至我最后更新的知识点（2023 年），Domain 模块已被废弃，并不推荐在新的项目中使用，因为它可能在未来的版本中被移除。

不过，为了理解 Domain 的概念和作用，我们可以简单地介绍一下它的基本用途。在 Node.js 中，异步编程是非常常见的，事件驱动的设计使得错误处理变得复杂，因为错误可能在任何时间发生，在任何异步调用的回调函数中。Domain 提供了一种将这些异步操作封装起来的方式，这样当其中一个操作出现错误时，整个“域”都可以对该错误作出反应。

让我们通过一个简化的例子来说明 Domain 如何工作：

```javascript
const domain = require("domain");

// 创建一个 domain 实例
const d = domain.create();

d.on("error", function (err) {
  console.log("捕获到错误:", err);
});

// 在 domain 的上下文中运行异步函数
d.run(function () {
  // 这里是一个可能会抛出错误的异步操作
  setTimeout(function () {
    throw new Error("意外的错误");
  }, 1000);
});
```

在这个例子中，我们首先通过 `require('domain')` 引入了 `Domain` 模块，并创建了一个新的 domain 实例。然后我们监听 `error` 事件，这意味着如果在这个 domain 中的任何代码抛出错误，这个监听函数将会被调用。接着，我们使用 `d.run()` 方法在 domain 的上下文中执行一段异步代码，在这个例子中是通过 `setTimeout` 设置的延迟函数。如果这段代码中抛出了错误，它将不会导致程序崩溃，而是触发 domain 的 `error` 事件，并执行我们设定的错误处理逻辑。

Node.js 开发团队建议开发者避免使用 Domain 模块，转而采用更加现代和可靠的错误处理机制，比如使用 Promises 和 `async/await`，以及使用 `try/catch` 块来捕获异步代码中的错误。例如：

```javascript
async function riskyOperation() {
  try {
    await someAsyncFunctionThatMightFail();
    // 更多的异步操作...
  } catch (err) {
    console.log("捕获到错误:", err);
  }
}

riskyOperation();
```

在这个现代的方法中，你使用 `async` 函数声明异步函数，并通过 `await` 关键字等待承诺（Promises）的结果。如果异步操作失败并抛出错误，`catch` 块将会捕获这个错误，你可以在那里处理错误。

总结：`Domain` 模块曾经是 Node.js 处理异步错误的一个机制，但由于它的缺陷和问题，已不再推荐使用。现代的 Node.js 错误处理推荐使用 Promises、`async/await` 和 `try/catch` 结构。

### [domain.members](https://nodejs.org/docs/latest/api/domain.html#domainmembers)

Node.js 的 `domain` 模块是一个废弃的（deprecated）特性，这意味着它可能在未来版本中被移除，并且不推荐在新项目中使用。这个模块最初被设计用来处理异常管理和将多个异步操作捆绑在一起以便于错误处理。

尽管不建议学习或使用已废弃的功能，但既然您问到了 `domain.members`，那我就会为您解释一下这个属性。

`domain.members` 是一个数组，它包含了所有添加到某个特定 domain 对象的 `EventEmitter` 对象或者具有 `Domain` 行为的对象。这里的 `EventEmitter` 是 Node.js 中的一个核心类，用于处理事件和回调。

一个简单的例子可以帮助你理解 `domain.members`：

```javascript
const domain = require("domain");
const EventEmitter = require("events").EventEmitter;

// 创建一个 domain 实例
const myDomain = domain.create();

// 创建一个 EventEmitter 实例并添加到 domain
const myEmitter1 = new EventEmitter();
myDomain.add(myEmitter1);

// 创建另一个 EventEmitter 实例并添加到 domain
const myEmitter2 = new EventEmitter();
myDomain.add(myEmitter2);

// 此时 domain.members 包含了我们刚刚添加进去的两个 EventEmitter 实例
console.log(myDomain.members); // 输出：[EventEmitter {}, EventEmitter {}]
```

在这个例子中，`myDomain.members` 数组包含了 `myEmitter1` 和 `myEmitter2` 两个 `EventEmitter` 实例。如果这些实例中的任何一个发出错误事件，domain 可以拦截这个错误，允许开发者对其进行统一的处理。

再次重申，由于 `domain` 模块已经被标记为废弃，在实际开发中应该使用其他机制，如 `async/await` 结合 `try/catch` 块，或者使用 `Promise` 来处理异步代码中的错误。这些现代的错误处理方案更加稳定、可靠，并且得到了社区的广泛支持。

### [domain.add(emitter)](https://nodejs.org/docs/latest/api/domain.html#domainaddemitter)

Node.js 的 `domain` 模块是一个处理多个异步操作中未被捕获错误的旧有解决方案。由于 `domain` 模块已被废弃，它不应用于新代码。而且，在 Node.js v21.7.1 的文档中，`domain` 模块可能根本不存在或者不提供任何有效的功能。相反，现代的 Node.js 开发推荐使用其他错误处理策略，例如 async/await 结合 try/catch 块，或者使用类似于 domains 功能的第三方库。

如果你正在查看的是老版本的 Node.js 文档，`domain.add(emitter)` 方法是这样的：

在历史版本中，`domain` 模块被用来简化异步代码的错误处理。每个 domain 都可以看做是一个错误处理的上下文。`domain.add(emitter)` 方法允许你将一个 EventEmitter 实例添加到特定的 domain 中，这意味着一旦该 EventEmitter 实例触发了一个 'error' 事件，它将被当前 domain 捕获和处理。

下面通过一个例子来说明这是怎么工作的：

```javascript
const domain = require("domain");
const EventEmitter = require("events");

// 创建一个新的 domain
const d = domain.create();

d.on("error", function (err) {
  console.log("Domain 捕获到错误:", err.message);
});

// 创建一个 EventEmitter 实例
const emitter = new EventEmitter();

// 将这个 emitter 添加到 domain
d.add(emitter);

// 这里模拟一个异步操作
process.nextTick(function () {
  // 这里故意触发一个错误
  emitter.emit("error", new Error("手动抛出一个错误"));
});
```

在这个例子中，我们创建了一个名为 `d` 的 domain，并且定义了一个错误处理函数，它会在 domain 捕获到错误时执行。接着，我们创建了一个 EventEmitter 实例 `emitter`，并将其添加到 domain `d`。然后我们模拟一个异步操作，在 next tick 中，我们故意让 `emitter` 触发了一个 'error' 事件。正常情况下，如果没有适当的监听器，这个错误会导致程序崩溃。但是因为 `emitter` 已经被添加到了 `d` domain 中，所以当 'error' 事件被触发时，`d` domain 的错误处理函数就会被调用。

再次强调，由于 `domain` 模块已被 Node.js 标记为废弃，并且在最新的 Node.js 版本中不再提供支持，你应该寻找其他方法来处理异步错误。比如使用 Promise 和 async/await，这样可以更简单、直接地进行错误处理：

```javascript
//来源：doc.cherrychat.org 请勿rw哒商用doc.cherrychat.org
async function someAsyncFunction() {
  try {
    // 执行一些异步操作...
  } catch (err) {
    console.error("捕获到错误:", err.message);
  }
}
```

在这个更新的示例中，我们使用了 async 函数和 try/catch 来捕获可能发生的错误。这是现代 Node.js 编程中推荐的做法。

### [domain.bind(callback)](https://nodejs.org/docs/latest/api/domain.html#domainbindcallback)

Node.js 的 `domain` 模块是一个在 Node.js v10.0.0 版本中被弃用的模块，它被用来处理和拦截异步代码中抛出的错误。即便如此，了解一下这个概念还是有帮助的。

首先，你需要知道，在编程中，"domain" 是一种抽象概念，用于表示一系列的操作和流程被视为属于同一个组或域。在 Node.js 中，`domain` 模块允许你将不同的 I/O 操作（例如读写文件、网络请求等）分组到一个域中，从而在出现异常时能统一捕获和处理错误。

`domain.bind(callback)` 函数用于创建一个新的函数，当这个新函数被调用时，任何在该函数内部发生的错误都会被当前活跃的 domain 所捕获。如果没有活跃的 domain，那么这个函数的行为就和普通函数没有区别。

让我们举一个实际的例子来说明 `domain.bind(callback)` 之前的用法：

```javascript
const domain = require("domain");

// 创建一个域
const d = domain.create();

// 当域内发生错误时的处理逻辑
d.on("error", (err) => {
  console.error(`捕获到错误：${err.message}`);
});

function riskyFunction() {
  // 这里可能会抛出错误的代码
  throw new Error("出错啦！");
}

// 使用 bind 将 riskyFunction 绑定到域
const boundFunction = d.bind(riskyFunction);

// 运行绑定到域的函数
boundFunction();
```

在这个例子中，`riskyFunction` 是一个可能会抛出错误的函数。通过使用 `domain.bind()` 方法，我们创建了一个新的函数 `boundFunction`，当这个函数执行并且遇到错误时，这个错误不会直接导致程序崩溃，而是会被 `d.on('error', callback)` 中定义的错误处理函数所捕获。

然而，需要强调的是，由于 `domain` 模块已经被弃用，推荐的做法是使用其他方式来进行错误处理，比如 async/await 结合 try/catch 块来处理异步代码中的异常：

```javascript
async function riskyFunction() {
  // 这里可能会抛出错误
  throw new Error("出错啦！");
}

async function runFunction() {
  try {
    await riskyFunction();
  } catch (err) {
    console.error(`捕获到错误：${err.message}`);
  }
}

runFunction();
```

在这个经过更新的例子中，我们使用了 `async/await` 来处理异步操作，并用 `try/catch` 来捕获 `riskyFunction` 中可能抛出的错误。

总结一下，尽管你可能不会在新项目中使用 `domain` 模块，但了解它的原理对于理解 Node.js 错误处理机制仍然有益处。在实际应用中，请使用更现代的方法来处理错误。

### [domain.enter()](https://nodejs.org/docs/latest/api/domain.html#domainenter)

Node.js 的 `domain` 模块是一个用于简化异步代码中多个 IO 操作的错误处理的模块。然而，值得注意的是，截至我所掌握的知识更新（2023 年前），Node.js 官方已经将这个模块标记为 `Deprecated`，也就是说它被认为是过时的，并且可能在将来的版本中移除，因此不建议在新的项目中使用。

即使如此，我会解释一下 `domain.enter()` 是做什么的，并给出实际例子，但请记住考虑替代的方法来处理错误，比如使用 `async/await` 结合 `try/catch`，或者使用诸如 `Promises` 的现代 JavaScript 特性。

`domain.enter()` 方法是当你想要显式地将一个给定的函数调用放入到一个特定的 domain 中时使用的。一个 domain 基本上充当了一个错误处理的上下文，可以捕获在这个上下文中发生的任何异步错误。

以下是一个简单的示例：

```javascript
const domain = require("domain");
const fs = require("fs");

// 创建一个 domain 实例
const d = domain.create();

d.on("error", (err) => {
  // 在这个域内的任何错误都会触发这里的回调
  console.error(`Domain caught error: ${err.message}`);
});

// 进入域
d.run(() => {
  // 使用 domain.enter() 显示进入域
  d.enter();

  // 执行一些异步操作，如文件读取
  fs.readFile("nonexistent.txt", "utf8", (err, data) => {
    if (err) {
      // 故意抛出错误，看看是否能够被域捕获
      throw err;
    }

    console.log(data);

    // 使用 domain.exit() 可以退出当前域，不再捕获之后的错误
    d.exit();
  });
});
```

在这个例子中，我们创建了一个新的 domain 实例，定义了一个错误处理函数。然后我们使用 `d.run()` 来运行一段代码，并在其中手动调用 `d.enter()` 来确保我们显式地进入了这个域。接下来我们执行一个异步的文件读取操作，如果文件不存在，则会产生一个错误，由于这个操作是在 domain 的上下文中进行的，所以这个错误会被 domain 捕获并传递给我们之前注册的错误处理函数。

需要强调的是，由于 `domain` 模块被废弃，这种错误处理方式不是推荐的做法，而且可能在未来的 Node.js 版本中完全无法使用。正确处理异步错误的现代方法包括使用 Promises 和 async/await 语法，通过 try/catch 块来捕获错误。

### [domain.exit()](https://nodejs.org/docs/latest/api/domain.html#domainexit)

好的，我会直接进入主题。

Node.js 中的 `domain` 模块是一个在 Node.js v21.7.1 版本中已经被废弃的功能。它最初目的是简化多个异步操作中错误处理的复杂性。但由于一些问题和限制，它不再是推荐使用的方法，并且未来的 Node.js 版本可能会完全移除它。

尽管如此，我将会解释 `domain.exit()` 方法是做什么的，以及它曾经如何使用，但请记住在新的代码中不应该使用 `domain` 模块，而是寻求其他现代化的错误处理策略，例如使用 `async/await` 结合 try/catch 块等。

### domain.exit()

当你使用 `domain.enter()` 将一段代码的执行上下文与特定的域（domain）相关联时，所有在这段代码中触发的异步操作都会成为该域的一部分。这意味着，如果这些异步操作中的任何一个抛出了错误，它们将被该域捕获。

相对地，`domain.exit()` 方法用于退出当前的域上下文。调用它之后，新的异步操作将不再关联到该域，即它们的错误不会被该域捕获。

这里值得注意的是，`domain.enter()` 和 `domain.exit()` 必须配对使用，以确保域的进入和退出动作可以正确匹配。

### 实际例子

虽然不推荐在新项目中使用，我们还是可以举个例子说明 `domain.exit()` 是如何工作的：

```javascript
const domain = require("domain");

// 创建一个域
const d = domain.create();

d.on("error", (err) => {
  console.log("捕获到错误：", err);
});

d.run(() => {
  // 进入域
  d.enter();

  // 这个 setTimeout 的回调函数属于域 d
  setTimeout(() => {
    console.log("这段代码运行在域中");
    throw new Error("错误会被域 d 捕获");
  }, 100);

  // 退出域
  d.exit();

  // 这个 setTimeout 的回调函数不属于任何域
  setTimeout(() => {
    console.log("这段代码不运行在域中");
    throw new Error("这个错误不会被域 d 捕获，而是导致程序崩溃");
  }, 200);
});
```

在上面的例子中，第一个 `setTimeout` 在域 `d` 中执行，所以当它抛出错误时，错误会被域 `d` 所捕获。第二个 `setTimeout` 在调用 `d.exit()` 之后排定，所以即便它在相同的 `run()` 回调内，它抛出的错误也不会被域 `d` 所捕获，而是会导致一个未捕获异常，通常会导致 Node.js 的进程崩溃。

### 总结和建议

- **不要在新代码中使用 `domain` 模块**，因为它已经被 Node.js 核心团队废弃。
- 对于错误处理，请考虑使用更现代的机制，比如 `async/await` 加上 `try/catch`，或者使用诸如 Promise 或 EventEmitter 来处理异步错误。
- 如果你正在维护旧的代码库并且需要理解 `domain` 模块的工作方式，仔细测试相关代码，并计划将其迁移到推荐的错误处理模式。

### [domain.intercept(callback)](https://nodejs.org/docs/latest/api/domain.html#domaininterceptcallback)

好的，我会尽量用简单的语言来解释`domain.intercept(callback)`这个方法的作用和如何使用。

首先，需要说明的是，Node.js 的 `domain` 模块已经被标记为废弃（deprecated），这意味着未来的 Node.js 版本可能会移除这个模块，并且不推荐在新的代码中使用它。但是，为了回答你的问题，我们可以讨论一下它在 v21.7.1 中的行为。

`domain` 模块主要用于处理异常（errors）。在 JavaScript 中，当一个异步操作失败时，通常会通过回调函数的第一个参数传递错误对象。比如：

```javascript
fs.readFile("somefile.txt", function (err, data) {
  if (err) {
    // 处理错误
    console.error("读取文件时发生错误:", err);
  } else {
    // 使用文件数据
    console.log(data);
  }
});
```

在上面的例子中，如果 `readFile` 函数遇到错误，它会把错误对象作为回调函数的第一个参数传递给 `err`。这是 Node.js 中常见的错误处理模式，称为“错误优先”（error-first）回调。

但是，使用 `domain.intercept(callback)` 方法可以使错误处理变得更简洁。这个方法返回一个新的回调函数，当原始回调应该被执行时，它会自动处理错误。如果有错误发生，它会将错误发送给 domain 对象，而不是调用原始回调函数。

举个实际的例子：

```javascript
const domain = require("domain");
const fs = require("fs");

// 创建一个 domain 实例
const d = domain.create();

d.on("error", (err) => {
  // 这里可以处理所有通过 domain.intercept 发送过来的错误
  console.error("捕获到错误:", err);
});

// 假设我们有一个异步操作，例如读取文件
function readFile(filename, cb) {
  fs.readFile(
    filename,
    d.intercept((data) => {
      // 如果没有错误发生，这个回调就会被执行
      // 我们可以处理文件数据
      cb(null, data);
    })
  );
}

// 使用 domain 封装的 readFile 函数
readFile("somefile.txt", (err, data) => {
  if (err) {
    // 错误会在 domain 的 'error' 事件中被捕获，所以这里不会接收到错误
  } else {
    // 处理文件内容
    console.log(data);
  }
});

// 故意读取一个不存在的文件，引发错误
readFile("nonexistent.txt", (err, data) => {
  // 这里同样不会接收到错误，因为错误已经被 domain 捕获
});
```

在以上代码中，我们创建了一个 domain，并且为它添加了一个监听错误的事件处理器。然后我们定义了一个 `readFile` 函数，它使用 `fs.readFile` 来读取文件内容，并通过 `d.intercept` 包装了原始的回调。当 `fs.readFile` 成功读取文件时，`d.intercept` 返回的函数就会调用原始的回调并传递文件数据。如果 `fs.readFile` 失败，错误会被发送到 domain 对象，并通过 'error' 事件来处理，而不是调用回调函数。

需要注意的是，虽然 `domain` 模块提供了一种错误处理机制，但由于它可能会导致内存泄漏等问题，现在推荐使用其他机制，比如 `async/await` 和 `Promise` 结合 `try/catch` 来处理异步错误。

### [domain.remove(emitter)](https://nodejs.org/docs/latest/api/domain.html#domainremoveemitter)

Node.js 中的`domain`模块是一个用于简化多个异步操作中错误处理的工具。请注意，当前这个模块已被废弃，并不推荐在新的代码中使用。尽管如此，我还是会为你解释一下`domain.remove(emitter)`方法的用法。

首先来了解下背景：在 Node.js 中，`EventEmitter`对象可以发出事件（events），而其他部分的代码可以通过监听这些事件来响应。常见的`EventEmitter`实例包括 HTTP 服务器、文件流等。

`domain`模块允许你创建一个域（domain），你可以将一个或多个`EventEmitter`实例添加到这个域中。这样做的目的是当任何被域捕获的`EventEmitter`实例发生错误时，所有的错误都会被重定向到这个域的错误处理器上，而不是默认地让程序崩溃。这就给了我们处理错误的机会，比如记录日志、清理资源等，然后优雅地关闭程序或者继续运行。

`domain.remove(emitter)`方法用于从一个域中移除一个`EventEmitter`实例。这意味着一旦你调用了这个方法，如果这个`EventEmitter`实例发生错误，错误就不会再被该域捕获，而是会按照其它方式进行处理，例如全局的`uncaughtException`事件处理器，或者导致进程崩溃（如果没有相应的处理器）。

以下是一个例子：

假设你创建了一个 HTTP 服务器，它在处理请求时可能会产生错误。你想要确保这些错误能够被捕获并且记录下来，同时服务器能够继续运行。

```javascript
const http = require("http");
const domain = require("domain");

// 创建一个域
const d = domain.create();

// 当域内的错误发生时的处理逻辑
d.on("error", (err) => {
  console.error(`捕获到错误: ${err.message}`);
  // 在这里，你可以记录错误日志，关闭资源等操作
});

// 创建HTTP服务器
const server = http.createServer((req, res) => {
  // 模拟处理请求过程中可能出现的错误
  if (req.url === "/error") {
    throw new Error("故意抛出错误");
  }
  res.writeHead(200);
  res.end("Hello World\n");
});

// 将服务器实例添加到域中
d.add(server);

server.listen(8080, () => {
  console.log("服务器运行在 http://localhost:8080/");
});

// 假设某个时间点之后，你决定不再通过域来处理服务器的错误
setTimeout(() => {
  d.remove(server);
  console.log("HTTP服务器已经从域中移除，不再由域处理错误。");
}, 60000); //60秒后执行
```

在上面的例子中，我们创建了一个简单的 HTTP 服务器，使得当你访问 `/error` 路径时，服务器会故意抛出一个错误。这个错误本来会导致进程崩溃，但因为我们把服务器实例放入了一个域中，所以域会捕获并处理这个错误。

随后，我们设置了一个定时器，在 60 秒后执行`d.remove(server)`，这样从那之后，如果再有错误发生，域就不会再捕获这些错误了。

最后，请记住，由于`domain`模块已被废弃，实际开发中建议使用诸如`async/await`结合`try/catch`、`Promise`链式调用中的`.catch()`方法等现代 JavaScript 错误处理机制，或者使用专门针对错误管理的库。

### [domain.run(fn[, ...args])](https://nodejs.org/docs/latest/api/domain.html#domainrunfn-args)

`domain.run(fn[, ...args])` 是 Node.js 中 `domain` 模块的一个方法。不过，在我详细解释这个方法之前，需要告诉你一个重要的信息：Node.js 官方文档指出，`domain` 模块已被弃用（deprecated）。这意味着官方建议不要在新的项目中使用它，并且未来的 Node.js 版本可能会完全移除这个模块。

尽管如此，为了回答你的问题，我们将假设你正在使用它作为学习目的，或者在维护一个早期代码库。

`domain` 模块最初设计用于简化异步代码中错误处理的复杂性。在异步操作中，如果没有正确的错误处理，一个操作中发生的错误可能很难追踪到它源头的调用栈。`domain` 提供了一种方式来捕获这些异步操作中的错误。

现在，让我们看看 `domain.run(fn[, ...args])` 方法是什么：

- `fn` 是你想要执行的函数。
- `[...args]` 是传递给该函数的参数。

当你调用 `domain.run(fn[, ...args])` 时，它会立即执行函数 `fn`，并传入任何提供的参数 `...args`。如果在执行 `fn` 的过程中，有任何错误发生，这些错误会被捕获并触发 `domain` 的 `'error'` 事件。

这里是一个虚构的例子来解释这个概念：

```javascript
const domain = require("domain");

// 创建一个域
const d = domain.create();

// 监听域上的错误事件
d.on("error", (err) => {
  console.error("捕获到错误:", err);
});

// 定义一个可能会抛出错误的函数
function riskyFunction(a, b) {
  if (typeof a !== "number" || typeof b !== "number") {
    throw new Error("参数必须是数字类型");
  }
  return a + b;
}

// 使用 domain.run 运行可能会抛出错误的函数
d.run(riskyFunction, 1, "b"); // 这里第二个参数故意传入非数字来引发错误

// 结果会是监听器捕获到错误并打印 "捕获到错误: Error: 参数必须是数字类型"
```

在这个例子中，我们创建了一个域 `d` 并对其添加了错误处理。然后我们定义了一个可能会抛出错误的函数 `riskyFunction`，最后我们通过 `d.run()` 来运行这个函数并故意传入错误的参数以此来触发错误。因为这个错误发生在域中，所以域的错误处理器会捕获到它，并打印出错误信息。

但是请记得，由于 `domain` 模块的弃用，现在推荐使用其他错误处理策略来处理异步操作中的错误，例如使用 `async/await` 结合 `try/catch` 块，或者在 Promise 链中使用 `.catch()` 方法。

## [Domains and promises](https://nodejs.org/docs/latest/api/domain.html#domains-and-promises)

Node.js 的 Domain 模块是一个不推荐使用的（deprecated）特性，它被用来处理多个异步操作中未捕获的异常，以便可以更加容易地追踪错误发生的上下文环境。但随着 Node.js 版本的发展和更好的错误处理模式（如 Promises 和 async/await）的出现，Domain 模块变得几乎不再需要了。

Promises 是处理 Node.js 中异步操作的一种方式。一个 Promise 代表一个最终可能完成或失败的异步操作，并且它有三种状态：

1. **Pending**：初始状态，既没有完成也没有失败。
2. **Fulfilled**：意味着操作成功完成。
3. **Rejected**：意味着操作失败。

在 Node.js v21.7.1 的文档中，提到了“Domains and promises”的结合使用，尽管 Domains 是不推荐使用的，但如果你还在使用它们，应当知道 Domains 与 Promises 的互动方式。

在这里我会给你一个简化的解释，然后提供一个例子。

### 简化解释

当你在 Node.js 中使用 Domain 来捕获异步操作产生的错误时，如果这些异步操作返回的是 Promise，那么在 Promise 被 reject（拒绝）时，即使你在 Promise 链中有 `.catch()` 处理错误，Domain 仍然可以捕获到这个错误。这样做的目的是为了确保在任何异步操作中出现的错误都能够被 Domain 捕获并进行处理。

### 实际运用示例

假设我们有一个 Node.js 应用，其中包含一个异步函数 `asyncFunction` ，它会返回一个可能被 reject 的 Promise。

```javascript
const domain = require("domain");

// 创建一个新的 domain
const d = domain.create();

d.on("error", (err) => {
  console.log("捕获到错误:", err);
});

// 这是一个返回 Promise 的异步函数
function asyncFunction() {
  return new Promise((resolve, reject) => {
    // 在这里做一些异步的操作，并且可能会失败
    const errorOccurred = true;
    if (errorOccurred) {
      reject(new Error("异步操作失败了！"));
    } else {
      resolve("成功了！");
    }
  });
}

// 在 domain 的上下文中运行异步函数
d.run(() => {
  asyncFunction().catch((error) => {
    console.error("Promise 被拒绝：", error);
  });
});
```

在这个例子里，`asyncFunction` 返回了一个 Promise 对象，该对象立刻被 reject，并传递了一个错误信息 '异步操作失败了！'。在调用 `asyncFunction` 的同时，我们通过 `.catch()` 方法链式地添加了一个错误处理函数。

通常情况下，`.catch()` 会捕获 Promise 中的错误，并且错误不会去触发 Domain 的 'error' 事件。但是，由于 Promises 和 Domains 的集成，即使错误已经在 `.catch()` 中被处理了，Domain 仍然可以捕获到这个错误，并执行定义在 `d.on('error', ...)` 中的错误处理代码。

这种行为对于确保所有的错误都能被捕获很有帮助，尤其是在大型应用程序中，可能某处忘记了正确地处理 Promise 错误。然而，因为 Domains 已经不推荐使用了，所以在新的项目中，你应该使用其他现代的错误处理机制，例如使用 `async/await` 结合 `try/catch` 块来优雅地处理异步代码中的错误。
